<?xml version="1.0" ?>
<!-- =================================================================================== -->
<!-- |    This document was autogenerated by xacro from edumip_my_robot.xacro          | -->
<!-- |    EDITING THIS FILE BY HAND IS NOT RECOMMENDED                                 | -->
<!-- =================================================================================== -->
<robot name="EduMIP" xmlns:xacro="http://www.ros.org/wiki/xacro">
  <material name="body">
    <color rgba="0 0 0.8 1"/>
  </material>
  <material name="wheel">
    <color rgba="1 1 1 1"/>
  </material>
  <link name="edumip_body">
    <visual>
      <origin xyz="0 0 0"/>
      <geometry>
        <box size="0.035 0.05 0.1"/>
      </geometry>
      <material name="body"/>
    </visual>
    <collison>
      <origin xyz="0 0 0"/>
      <geometry>
        <box size="0.035 0.05 0.1"/>
      </geometry>
    </collison>
    <inertial>
      <origin xyz="0 0 -0.2"/>
      <mass value="1"/>
      <inertia ixx="1" ixy="0" ixz="0" iyy="1" iyz="0" izz="0"/>
    </inertial>
  </link>
  <link name="wheelL">
    <visual>
      <origin rpy="1.57075 0 0" xyz="0 -0.01 0"/>
      <material name="wheel"/>
      <geometry>
        <cylinder length="0.01" radius="0.034"/>
      </geometry>
    </visual>
    <collision>
      <origin rpy="1.57075 0 0" xyz="0 -0.01 0"/>
      <geometry>
        <cylinder length="0.01" radius="0.034"/>
      </geometry>
    </collision>
    <inertial>
      <origin rpy="1.57075 0 0" xyz="0 -0.01 0"/>
      <mass value="0.2"/>
      <inertia ixx="0.2" ixy="0" ixz="0" iyy="0.2" iyz="0" izz="0.2"/>
    </inertial>
  </link>
  <link name="wheelR">
    <visual>
      <origin rpy="1.57075 0 0" xyz="0 0.01 0"/>
      <material name="wheel"/>
      <geometry>
        <cylinder length="0.01" radius="0.034"/>
      </geometry>
    </visual>
    <collision>
      <origin rpy="1.57075 0 0" xyz="0 0.01 0"/>
      <geometry>
        <cylinder length="0.01" radius="0.034"/>
      </geometry>
    </collision>
    <inertial>
      <origin rpy="1.57075 0 0" xyz="0 0.01 0"/>
      <mass value="0.2"/>
      <inertia ixx="0.2" ixy="0" ixz="0" iyy="0.2" iyz="0" izz="0.2"/>
    </inertial>
  </link>
  <joint name="wheelL_joint" type="continuous">
    <parent link="edumip_body"/>
    <child link="wheelL"/>
    <axis xyz="0 1 0"/>
    <origin rpy="0 0 0" xyz="0 -0.025 -0.05"/>
    <dynamics friction="0.7"/>
  </joint>
  <joint name="wheelR_joint" type="continuous">
    <parent link="edumip_body"/>
    <child link="wheelR"/>
    <axis xyz="0 1 0"/>
    <origin rpy="0 0 0" xyz="0 0.025 -0.05"/>
    <dynamics friction="0.7"/>
  </joint>
  <gazebo reference="edumip_body">
    <material>Gazebo/Blue</material>
    <mu1>0.2</mu1>
    <mu2>0.2</mu2>
  </gazebo>
  <gazebo reference="wheelR">
    <material>Gazebo/Green</material>
    <mu1>0.2</mu1>
    <mu2>0.2</mu2>
  </gazebo>
  <gazebo reference="wheelL">
    <material>Gazebo/Red</material>
    <mu1>0.2</mu1>
    <mu2>0.2</mu2>
  </gazebo>
</robot>

